<mujoco model="biped_schematics">
  <compiler angle="radian" meshdir="/Users/cr/Downloads/biped_schematics/meshes/" autolimits="true"/>
  <statistic meansize="0.101066" extent="1.16965" center="0.0761517 0 -0.135643"/>
  <asset>
    <mesh name="base_link" file="base_link.stl" scale="0.001 0.001 0.001"/>
    <mesh name="hip_2" file="hip_2.stl" scale="0.001 0.001 0.001"/>
    <mesh name="hip_1" file="hip_1.stl" scale="0.001 0.001 0.001"/>
    <mesh name="hip2_1" file="hip2_1.stl" scale="0.001 0.001 0.001"/>
    <mesh name="hip2_2" file="hip2_2.stl" scale="0.001 0.001 0.001"/>
    <mesh name="thigh_1" file="thigh_1.stl" scale="0.001 0.001 0.001"/>
    <mesh name="thigh_2" file="thigh_2.stl" scale="0.001 0.001 0.001"/>
    <mesh name="shank_1" file="shank_1.stl" scale="0.001 0.001 0.001"/>
    <mesh name="shank_2" file="shank_2.stl" scale="0.001 0.001 0.001"/>
    <mesh name="ankle_1" file="ankle_1.stl" scale="0.001 0.001 0.001"/>
    <mesh name="ankle_2" file="ankle_2.stl" scale="0.001 0.001 0.001"/>
    <mesh name="foot_1" file="foot_1.stl" scale="0.001 0.001 0.001"/>
    <mesh name="foot_2" file="foot_2.stl" scale="0.001 0.001 0.001"/>
    <mesh name="top_body_1" file="top_body_1.stl" scale="0.001 0.001 0.001"/>
  </asset>
  <worldbody>
    <geom type="mesh" contype="0" conaffinity="0" group="1" density="0" mesh="base_link"/>
    <geom type="mesh" mesh="base_link"/>
    <geom type="mesh" contype="0" conaffinity="0" group="1" density="0" mesh="top_body_1"/>
    <geom type="mesh" mesh="top_body_1"/>
    <body name="hip_2" pos="0 0.075 0">
      <inertial pos="0.0594432 0 0" quat="0 0.707107 0 0.707107" mass="1.90413" diaginertia="0.00194557 0.00125193 0.00119981"/>
      <joint name="hip_x_left" pos="0 0 0" axis="1 0 0" range="-0.785398 0.785398"/>
      <geom pos="0 -0.075 0" type="mesh" contype="0" conaffinity="0" group="1" density="0" mesh="hip_2"/>
      <body name="hip2_1" pos="0.06 0 -0.02">
        <inertial pos="0 0 -0.07" quat="0.5 0.5 -0.5 0.5" mass="4.50976" diaginertia="0.00683402 0.00683402 0.00615179"/>
        <joint name="hip_z_left" pos="0 0 0" axis="0 0 -1" range="-0.5 0.5"/>
        <geom pos="-0.06 -0.075 0.02" type="mesh" contype="0" conaffinity="0" group="1" density="0" mesh="hip2_1"/>
        <geom pos="-0.06 -0.075 0.02" type="mesh" mesh="hip2_1"/>
        <body name="thigh_1" pos="0 0 -0.07">
          <inertial pos="0.0152464 0 -0.174267" quat="0.706434 -0.0308436 -0.0308436 0.706434" mass="1.10913" diaginertia="0.00499482 0.00434498 0.00111198"/>
          <joint name="hip_y_left" pos="0 0 0" axis="0 1 0" range="-1.5708 1.0472"/>
          <geom pos="-0.06 -0.075 0.09" type="mesh" contype="0" conaffinity="0" group="1" density="0" mesh="thigh_1"/>
          <geom pos="-0.06 -0.075 0.09" type="mesh" mesh="thigh_1"/>
          <body name="shank_1" pos="0.020917 0 -0.239087">
            <inertial pos="-0.0107979 0 -0.123425" quat="0.706434 0.0308436 0.0308436 0.706434" mass="2.59106" diaginertia="0.00309062 0.00282473 0.001746"/>
            <joint name="knee_left" pos="0 0 0" axis="0 1 0" range="-0.5 1.5708"/>
            <geom pos="-0.080917 -0.075 0.329087" type="mesh" contype="0" conaffinity="0" group="1" density="0" mesh="shank_1"/>
            <body name="ankle_1" pos="-0.02266 0 -0.25901">
              <inertial pos="-1.09986e-07 0 -4.047e-07" quat="0.5 0.5 -0.5 0.5" mass="0.0786273" diaginertia="5.95976e-06 5.54236e-06 5.54236e-06"/>
              <joint name="ankle_y_left" pos="0 0 0" axis="0 1 0" range="-0.785398 0.785398"/>
              <geom pos="-0.058257 -0.075 0.588097" type="mesh" contype="0" conaffinity="0" group="1" density="0" mesh="ankle_1"/>
              <body name="foot_1">
                <inertial pos="0.0424999 0 -0.0350004" quat="0 0.707107 0 0.707107" mass="0.4452" diaginertia="0.00137363 0.00116958 0.00027083"/>
                <joint name="ankle_x_left" pos="0 0 0" axis="1 0 0" range="-0.523599 0.523599"/>
                <geom pos="-0.058257 -0.075 0.588097" type="mesh" contype="0" conaffinity="0" group="1" density="0" mesh="foot_1"/>
                <geom size="0.0875 0.04 0.015" pos="0.043 0 -0.035" type="box"/>
              </body>
            </body>
          </body>
        </body>
      </body>
    </body>
    <body name="hip_1" pos="0 -0.075 0">
      <inertial pos="0.0594432 0 0" quat="0 0.707107 0 0.707107" mass="1.90413" diaginertia="0.00194557 0.00125193 0.00119981"/>
      <joint name="hip_x_right" pos="0 0 0" axis="1 0 0" range="-0.785398 0.785398"/>
      <geom pos="0 0.075 0" type="mesh" contype="0" conaffinity="0" group="1" density="0" mesh="hip_1"/>
      <body name="hip2_2" pos="0.06 0 -0.02">
        <inertial pos="0 0 -0.07" quat="0.5 0.5 -0.5 0.5" mass="4.50976" diaginertia="0.00683402 0.00683402 0.00615179"/>
        <joint name="hip_z_right" pos="0 0 0" axis="0 0 -1" range="-0.5 0.5"/>
        <geom pos="-0.06 0.075 0.02" type="mesh" contype="0" conaffinity="0" group="1" density="0" mesh="hip2_2"/>
        <geom pos="-0.06 0.075 0.02" type="mesh" mesh="hip2_2"/>
        <body name="thigh_2" pos="0 0 -0.07">
          <inertial pos="0.0152464 0 -0.174267" quat="0.706434 -0.0308436 -0.0308436 0.706434" mass="1.10913" diaginertia="0.00499482 0.00434498 0.00111198"/>
          <joint name="hip_y_right" pos="0 0 0" axis="0 1 0" range="-1.5708 1.0472"/>
          <geom pos="-0.06 0.075 0.09" type="mesh" contype="0" conaffinity="0" group="1" density="0" mesh="thigh_2"/>
          <geom pos="-0.06 0.075 0.09" type="mesh" mesh="thigh_2"/>
          <body name="shank_2" pos="0.020917 0 -0.239087">
            <inertial pos="-0.0107979 0 -0.123425" quat="0.706434 0.0308436 0.0308436 0.706434" mass="2.59106" diaginertia="0.00309062 0.00282473 0.001746"/>
            <joint name="knee_right" pos="0 0 0" axis="0 1 0" range="-0.5 1.5708"/>
            <geom pos="-0.080917 0.075 0.329087" type="mesh" contype="0" conaffinity="0" group="1" density="0" mesh="shank_2"/>
            <body name="ankle_2" pos="-0.02266 0 -0.25901">
              <inertial pos="-1.09986e-07 0 -4.047e-07" quat="0.5 0.5 -0.5 0.5" mass="0.0786273" diaginertia="5.95976e-06 5.54236e-06 5.54236e-06"/>
              <joint name="ankle_y_right" pos="0 0 0" axis="0 1 0" range="-0.785398 0.785398"/>
              <geom pos="-0.058257 0.075 0.588097" type="mesh" contype="0" conaffinity="0" group="1" density="0" mesh="ankle_2"/>
              <body name="foot_2">
                <inertial pos="0.0424999 0 -0.0350004" quat="0 0.707107 0 0.707107" mass="0.4452" diaginertia="0.00137363 0.00116958 0.00027083"/>
                <joint name="ankle_x_right" pos="0 0 0" axis="1 0 0" range="-0.523599 0.523599"/>
                <geom pos="-0.058257 0.075 0.588097" type="mesh" contype="0" conaffinity="0" group="1" density="0" mesh="foot_2"/>
                <geom size="0.0875 0.04 0.015" pos="0.043 0 -0.035" type="box"/>
              </body>
            </body>
          </body>
        </body>
      </body>
    </body>
  </worldbody>
</mujoco>
